<?xml version="1.0" ?>
<!-- Generated using onshape-to-robot -->
<!-- Onshape document_id: 16c9706360b5ad34f9c8db49 -->
<mujoco model="simulation">
  <compiler angle="radian" meshdir="assets" autolimits="true"/>
  <default>
    <default class="simulation">
      <joint frictionloss="0.1" armature="0.005"/>
      <position kp="50" dampratio="1"/>
      <default class="visual">
        <geom type="mesh" contype="0" conaffinity="0" group="2"/>
      </default>
      <default class="collision">
        <geom group="3"/>
      </default>
    </default>
  </default>
  <!-- Additional sensors.xml -->
  <sensor>
    <accelerometer name="accel_sensor" site="imu_site"/>
    <gyro name="gyro_sensor" site="imu_site"/>
  </sensor>
  <!-- Additional joints_properties.xml -->
  <default>
    <default class="sts3215">
      <geom contype="0" conaffinity="0"/>
      <joint damping="0.60" frictionloss="0.052" armature="0.028"/>
      <position kp="17.8" kv="0.0" forcerange="-3.35 3.35"/>
    </default>
    <default class="backlash">
      <!-- +/- 0.5° of backlash -->
      <joint damping="0.01" frictionloss="0" armature="0.01" limited="true" range="-0.008726646259971648 0.008726646259971648"/>
    </default>
  </default>
  <worldbody>
    <!-- Link lamparm__base_elbow -->
    <body name="lamparm__base_elbow" pos="0 0 0" quat="1 0 0 0" childclass="simulation">
      <freejoint name="lamparm__base_elbow_freejoint"/>
      <inertial pos="0.0729066 -0.0229022 0.217607" mass="0.234138" fullinertia="0.0010919 0.00129476 0.000320305 7.35843e-05 -0.000504692 0.000161616"/>
      <!-- Part lamparm__base_elbow -->
      <geom type="mesh" class="visual" pos="0.0683802 0.000449515 0.192601" quat="0.149185 0.238014 -0.0370254 0.959021" mesh="lamparm__base_elbow" material="lamparm__base_elbow_material"/>
      <geom type="mesh" class="collision" pos="0.0683802 0.000449515 0.192601" quat="0.149185 0.238014 -0.0370254 0.959021" mesh="lamparm__base_elbow" material="lamparm__base_elbow_material"/>
      <!-- Part 金属舵盘_驱动__v2 -->
      <geom type="mesh" class="visual" pos="0.0947995 -0.0378086 0.310793" quat="0.794936 0.0912975 0.586898 -0.12366" mesh="金属舵盘_驱动__v2" material="金属舵盘_驱动__v2_material"/>
      <geom type="mesh" class="collision" pos="0.0947995 -0.0378086 0.310793" quat="0.794936 0.0912975 0.586898 -0.12366" mesh="金属舵盘_驱动__v2" material="金属舵盘_驱动__v2_material"/>
      <!-- Part 金属舵盘_从动__v2 -->
      <geom type="mesh" class="visual" pos="0.090674 -0.0701329 0.29168" quat="0.12366 0.586898 -0.0912975 0.794936" mesh="金属舵盘_从动__v2" material="金属舵盘_从动__v2_material"/>
      <geom type="mesh" class="collision" pos="0.090674 -0.0701329 0.29168" quat="0.12366 0.586898 -0.0912975 0.794936" mesh="金属舵盘_从动__v2" material="金属舵盘_从动__v2_material"/>
      <!-- Part pcb_chazuo_92 -->
      <geom type="mesh" class="visual" pos="0.110043 -0.0244059 0.276867" quat="0.794936 0.0912975 0.586898 -0.12366" mesh="pcb_chazuo_92" material="pcb_chazuo_92_material"/>
      <geom type="mesh" class="collision" pos="0.110043 -0.0244059 0.276867" quat="0.794936 0.0912975 0.586898 -0.12366" mesh="pcb_chazuo_92" material="pcb_chazuo_92_material"/>
      <!-- Part xg_ziji_16 -->
      <geom type="mesh" class="visual" pos="0.110043 -0.0244059 0.276867" quat="0.794936 0.0912975 0.586898 -0.12366" mesh="xg_ziji_16" material="xg_ziji_16_material"/>
      <geom type="mesh" class="collision" pos="0.110043 -0.0244059 0.276867" quat="0.794936 0.0912975 0.586898 -0.12366" mesh="xg_ziji_16" material="xg_ziji_16_material"/>
      <!-- Part ge_27 -->
      <geom type="mesh" class="visual" pos="0.101068 -0.0278417 0.301237" quat="0.497548 0.626662 0.327559 -0.50244" mesh="ge_27" material="ge_27_material"/>
      <geom type="mesh" class="collision" pos="0.101068 -0.0278417 0.301237" quat="0.497548 0.626662 0.327559 -0.50244" mesh="ge_27" material="ge_27_material"/>
      <!-- Part sg_ziji_15 -->
      <geom type="mesh" class="visual" pos="0.110043 -0.0244059 0.276867" quat="0.794936 0.0912975 0.586898 -0.12366" mesh="sg_ziji_15" material="sg_ziji_15_material"/>
      <geom type="mesh" class="collision" pos="0.110043 -0.0244059 0.276867" quat="0.794936 0.0912975 0.586898 -0.12366" mesh="sg_ziji_15" material="sg_ziji_15_material"/>
      <!-- Part zk_122 -->
      <geom type="mesh" class="visual" pos="0.110043 -0.0244059 0.276867" quat="0.794936 0.0912975 0.586898 -0.12366" mesh="zk_122" material="zk_122_material"/>
      <geom type="mesh" class="collision" pos="0.110043 -0.0244059 0.276867" quat="0.794936 0.0912975 0.586898 -0.12366" mesh="zk_122" material="zk_122_material"/>
      <!-- Part motor_1723_3 -->
      <geom type="mesh" class="visual" pos="0.101964 -0.0458133 0.276499" quat="0.147105 0.151998 0.977104 -0.0228836" mesh="motor_1723_3" material="motor_1723_3_material"/>
      <geom type="mesh" class="collision" pos="0.101964 -0.0458133 0.276499" quat="0.147105 0.151998 0.977104 -0.0228836" mesh="motor_1723_3" material="motor_1723_3_material"/>
      <!-- Link lamparm__wrist_head -->
      <body name="lamparm__wrist_head" pos="0.00583234 0.0182927 0.08291" quat="0.570913 -0.417203 0.570913 0.417203">
        <!-- Joint from lamparm__base_elbow to lamparm__wrist_head -->
        <joint axis="0 0 1" name="2" type="hinge" range="-1.0842575396713956 2.0573351139183975" class="sts3215"/>
        <inertial pos="0.0193636 0.000541554 -0.0196637" mass="0.0953804" fullinertia="1.16713e-05 2.19256e-05 1.7794e-05 -3.19269e-07 9.361e-07 6.98105e-08"/>
        <!-- Part lamparm__wrist_head -->
        <geom type="mesh" class="visual" pos="0.04111 7.30741e-16 -0.0192" quat="0.5 -0.5 -0.5 0.5" mesh="lamparm__wrist_head" material="lamparm__wrist_head_material"/>
        <geom type="mesh" class="collision" pos="0.04111 7.30741e-16 -0.0192" quat="0.5 -0.5 -0.5 0.5" mesh="lamparm__wrist_head" material="lamparm__wrist_head_material"/>
        <!-- Part 金属舵盘_驱动__v2_2 -->
        <geom type="mesh" class="visual" pos="-0.01 1.67203e-18 -0.027" quat="0.707107 0.707107 0 -5.47763e-32" mesh="金属舵盘_驱动__v2" material="金属舵盘_驱动__v2_material"/>
        <geom type="mesh" class="collision" pos="-0.01 1.67203e-18 -0.027" quat="0.707107 0.707107 0 -5.47763e-32" mesh="金属舵盘_驱动__v2" material="金属舵盘_驱动__v2_material"/>
        <!-- Part 金属舵盘_从动__v2_2 -->
        <geom type="mesh" class="visual" pos="0.01 -7.90727e-16 -0.05905" quat="9.30303e-15 -3.53884e-15 0.707107 -0.707107" mesh="金属舵盘_从动__v2" material="金属舵盘_从动__v2_material"/>
        <geom type="mesh" class="collision" pos="0.01 -7.90727e-16 -0.05905" quat="9.30303e-15 -3.53884e-15 0.707107 -0.707107" mesh="金属舵盘_从动__v2" material="金属舵盘_从动__v2_material"/>
        <!-- Part pcb_chazuo_92_2 -->
        <geom type="mesh" class="visual" pos="0.0255 6.87024e-16 -0.0096" quat="0.707107 0.707107 0 -5.47763e-32" mesh="pcb_chazuo_92" material="pcb_chazuo_92_material"/>
        <geom type="mesh" class="collision" pos="0.0255 6.87024e-16 -0.0096" quat="0.707107 0.707107 0 -5.47763e-32" mesh="pcb_chazuo_92" material="pcb_chazuo_92_material"/>
        <!-- Part xg_ziji_16_2 -->
        <geom type="mesh" class="visual" pos="0.0255 6.87024e-16 -0.0096" quat="0.707107 0.707107 0 -5.47763e-32" mesh="xg_ziji_16" material="xg_ziji_16_material"/>
        <geom type="mesh" class="collision" pos="0.0255 6.87024e-16 -0.0096" quat="0.707107 0.707107 0 -5.47763e-32" mesh="xg_ziji_16" material="xg_ziji_16_material"/>
        <!-- Part ge_27_2 -->
        <geom type="mesh" class="visual" pos="-1.80411e-16 3.21139e-16 -0.0156" quat="1.6825e-14 1 2.44606e-15 3.23662e-16" mesh="ge_27" material="ge_27_material"/>
        <geom type="mesh" class="collision" pos="-1.80411e-16 3.21139e-16 -0.0156" quat="1.6825e-14 1 2.44606e-15 3.23662e-16" mesh="ge_27" material="ge_27_material"/>
        <!-- Part sg_ziji_15_2 -->
        <geom type="mesh" class="visual" pos="0.0255 6.87024e-16 -0.0096" quat="0.707107 0.707107 0 -5.47763e-32" mesh="sg_ziji_15" material="sg_ziji_15_material"/>
        <geom type="mesh" class="collision" pos="0.0255 6.87024e-16 -0.0096" quat="0.707107 0.707107 0 -5.47763e-32" mesh="sg_ziji_15" material="sg_ziji_15_material"/>
        <!-- Part zk_122_2 -->
        <geom type="mesh" class="visual" pos="0.0255 6.87024e-16 -0.0096" quat="0.707107 0.707107 0 -5.47763e-32" mesh="zk_122" material="zk_122_material"/>
        <geom type="mesh" class="collision" pos="0.0255 6.87024e-16 -0.0096" quat="0.707107 0.707107 0 -5.47763e-32" mesh="zk_122" material="zk_122_material"/>
        <!-- Part motor_1723_3_2 -->
        <geom type="mesh" class="visual" pos="0.0255 0.00125 -0.03245" quat="0.5 0.5 0.5 0.5" mesh="motor_1723_3" material="motor_1723_3_material"/>
        <geom type="mesh" class="collision" pos="0.0255 0.00125 -0.03245" quat="0.5 0.5 0.5 0.5" mesh="motor_1723_3" material="motor_1723_3_material"/>
        <!-- Link scs215_v5 -->
        <body name="scs215_v5" pos="0.04111 7.30741e-16 -0.0192" quat="0.5 -0.5 -0.5 0.5">
          <!-- Joint from lamparm__wrist_head to scs215_v5 -->
          <joint axis="0 0 1" name="1" type="hinge" range="-5.021033992714066 1.2621513144655205" class="sts3215"/>
          <inertial pos="0.00584437 0.00206639 -0.0244202" mass="0.41735" fullinertia="0.00100304 0.00122902 0.00205034 -8.49257e-05 -8.64397e-06 -3.34823e-06"/>
          <!-- Part lamp_base -->
          <geom type="mesh" class="visual" pos="0.0119093 0.0037971 -0.0378" quat="0.590014 2.27628e-15 -1.55431e-15 0.807393" mesh="lamp_base" material="lamp_base_material"/>
          <geom type="mesh" class="collision" pos="0.0119093 0.0037971 -0.0378" quat="0.590014 2.27628e-15 -1.55431e-15 0.807393" mesh="lamp_base" material="lamp_base_material"/>
          <!-- Part lamp_base_cover -->
          <geom type="mesh" class="visual" pos="0.0119093 0.0037971 -0.0378" quat="0.590014 2.41506e-15 -1.88738e-15 0.807393" mesh="lamp_base_cover" material="lamp_base_cover_material"/>
          <geom type="mesh" class="collision" pos="0.0119093 0.0037971 -0.0378" quat="0.590014 2.41506e-15 -1.88738e-15 0.807393" mesh="lamp_base_cover" material="lamp_base_cover_material"/>
          <!-- Part 金属舵盘_驱动__v2_3 -->
          <geom type="mesh" class="visual" pos="-0.00952746 -0.00303768 -0.027" quat="0.698703 0.698703 0.10869 0.10869" mesh="金属舵盘_驱动__v2" material="金属舵盘_驱动__v2_material"/>
          <geom type="mesh" class="collision" pos="-0.00952746 -0.00303768 -0.027" quat="0.698703 0.698703 0.10869 0.10869" mesh="金属舵盘_驱动__v2" material="金属舵盘_驱动__v2_material"/>
          <!-- Part 金属舵盘_从动__v2_3 -->
          <geom type="mesh" class="visual" pos="0.00952746 0.00303768 -0.05905" quat="0.10869 -0.10869 0.698703 -0.698703" mesh="金属舵盘_从动__v2" material="金属舵盘_从动__v2_material"/>
          <geom type="mesh" class="collision" pos="0.00952746 0.00303768 -0.05905" quat="0.10869 -0.10869 0.698703 -0.698703" mesh="金属舵盘_从动__v2" material="金属舵盘_从动__v2_material"/>
          <!-- Part pcb_chazuo_92_3 -->
          <geom type="mesh" class="visual" pos="0.024295 0.00774608 -0.0096" quat="0.698703 0.698703 0.10869 0.10869" mesh="pcb_chazuo_92" material="pcb_chazuo_92_material"/>
          <geom type="mesh" class="collision" pos="0.024295 0.00774608 -0.0096" quat="0.698703 0.698703 0.10869 0.10869" mesh="pcb_chazuo_92" material="pcb_chazuo_92_material"/>
          <!-- Part xg_ziji_16_3 -->
          <geom type="mesh" class="visual" pos="0.024295 0.00774608 -0.0096" quat="0.698703 0.698703 0.10869 0.10869" mesh="xg_ziji_16" material="xg_ziji_16_material"/>
          <geom type="mesh" class="collision" pos="0.024295 0.00774608 -0.0096" quat="0.698703 0.698703 0.10869 0.10869" mesh="xg_ziji_16" material="xg_ziji_16_material"/>
          <!-- Part ge_27_3 -->
          <geom type="mesh" class="visual" pos="-1.19702e-17 3.78772e-17 -0.0156" quat="1.59242e-15 -0.988116 -0.153711 1.25707e-15" mesh="ge_27" material="ge_27_material"/>
          <geom type="mesh" class="collision" pos="-1.19702e-17 3.78772e-17 -0.0156" quat="1.59242e-15 -0.988116 -0.153711 1.25707e-15" mesh="ge_27" material="ge_27_material"/>
          <!-- Part sg_ziji_15_3 -->
          <geom type="mesh" class="visual" pos="0.024295 0.00774608 -0.0096" quat="0.698703 0.698703 0.10869 0.10869" mesh="sg_ziji_15" material="sg_ziji_15_material"/>
          <geom type="mesh" class="collision" pos="0.024295 0.00774608 -0.0096" quat="0.698703 0.698703 0.10869 0.10869" mesh="sg_ziji_15" material="sg_ziji_15_material"/>
          <!-- Part zk_122_3 -->
          <geom type="mesh" class="visual" pos="0.024295 0.00774608 -0.0096" quat="0.698703 0.698703 0.10869 0.10869" mesh="zk_122" material="zk_122_material"/>
          <geom type="mesh" class="collision" pos="0.024295 0.00774608 -0.0096" quat="0.698703 0.698703 0.10869 0.10869" mesh="zk_122" material="zk_122_material"/>
          <!-- Part motor_1723_3_3 -->
          <geom type="mesh" class="visual" pos="0.0239153 0.00893702 -0.03245" quat="0.417203 0.417203 0.570913 0.570913" mesh="motor_1723_3" material="motor_1723_3_material"/>
          <geom type="mesh" class="collision" pos="0.0239153 0.00893702 -0.03245" quat="0.417203 0.417203 0.570913 0.570913" mesh="motor_1723_3" material="motor_1723_3_material"/>
          <!-- Frame imu_site -->
          <site group="3" name="imu_site" pos="-3.4944e-17 4.02192e-17 -0.0378" quat="1.81174e-15 -0.590014 -0.807393 -2.8812e-15"/>
        </body>
      </body>
      <!-- Link lamparm__elbow_wrist -->
      <body name="lamparm__elbow_wrist" pos="0.105806 -0.0129789 0.301237" quat="0.575614 0.423658 -0.566139 0.410693">
        <!-- Joint from lamparm__base_elbow to lamparm__elbow_wrist -->
        <joint axis="0 0 1" name="3" type="hinge" range="-2.820024081304335 0.3215685722854582" class="sts3215"/>
        <inertial pos="-0.00212937 0.119295 0.0220282" mass="0.206448" fullinertia="0.000632713 4.80236e-05 0.000602863 -1.84707e-05 -1.72868e-06 -1.49987e-05"/>
        <!-- Part lamparm__elbow_wrist -->
        <geom type="mesh" class="visual" pos="-0.00618 0.08736 0.03925" quat="0.707107 -0.707107 0 -1.89876e-18" mesh="lamparm__elbow_wrist" material="lamparm__elbow_wrist_material"/>
        <geom type="mesh" class="collision" pos="-0.00618 0.08736 0.03925" quat="0.707107 -0.707107 0 -1.89876e-18" mesh="lamparm__elbow_wrist" material="lamparm__elbow_wrist_material"/>
        <!-- Part 金属舵盘_驱动__v2_4 -->
        <geom type="mesh" class="visual" pos="2.60902e-15 0.158185 -0.003875" quat="0.707107 -0 -0.707107 -1.10011e-16" mesh="金属舵盘_驱动__v2" material="金属舵盘_驱动__v2_material"/>
        <geom type="mesh" class="collision" pos="2.60902e-15 0.158185 -0.003875" quat="0.707107 -0 -0.707107 -1.10011e-16" mesh="金属舵盘_驱动__v2" material="金属舵盘_驱动__v2_material"/>
        <!-- Part 金属舵盘_从动__v2_4 -->
        <geom type="mesh" class="visual" pos="3.4972e-15 0.126135 0.016125" quat="1.77931e-14 0.707107 2.09832e-14 -0.707107" mesh="金属舵盘_从动__v2" material="金属舵盘_从动__v2_material"/>
        <geom type="mesh" class="collision" pos="3.4972e-15 0.126135 0.016125" quat="1.77931e-14 0.707107 2.09832e-14 -0.707107" mesh="金属舵盘_从动__v2" material="金属舵盘_从动__v2_material"/>
        <!-- Part pcb_chazuo_92_4 -->
        <geom type="mesh" class="visual" pos="5.55112e-17 0.175585 0.031625" quat="0.707107 -0 -0.707107 -1.10011e-16" mesh="pcb_chazuo_92" material="pcb_chazuo_92_material"/>
        <geom type="mesh" class="collision" pos="5.55112e-17 0.175585 0.031625" quat="0.707107 -0 -0.707107 -1.10011e-16" mesh="pcb_chazuo_92" material="pcb_chazuo_92_material"/>
        <!-- Part xg_ziji_16_4 -->
        <geom type="mesh" class="visual" pos="5.55112e-17 0.175585 0.031625" quat="0.707107 -0 -0.707107 -1.10011e-16" mesh="xg_ziji_16" material="xg_ziji_16_material"/>
        <geom type="mesh" class="collision" pos="5.55112e-17 0.175585 0.031625" quat="0.707107 -0 -0.707107 -1.10011e-16" mesh="xg_ziji_16" material="xg_ziji_16_material"/>
        <!-- Part ge_27_4 -->
        <geom type="mesh" class="visual" pos="3.88578e-16 0.169585 0.006125" quat="0.5 0.5 -0.5 0.5" mesh="ge_27" material="ge_27_material"/>
        <geom type="mesh" class="collision" pos="3.88578e-16 0.169585 0.006125" quat="0.5 0.5 -0.5 0.5" mesh="ge_27" material="ge_27_material"/>
        <!-- Part sg_ziji_15_4 -->
        <geom type="mesh" class="visual" pos="5.55112e-17 0.175585 0.031625" quat="0.707107 -0 -0.707107 -1.10011e-16" mesh="sg_ziji_15" material="sg_ziji_15_material"/>
        <geom type="mesh" class="collision" pos="5.55112e-17 0.175585 0.031625" quat="0.707107 -0 -0.707107 -1.10011e-16" mesh="sg_ziji_15" material="sg_ziji_15_material"/>
        <!-- Part zk_122_4 -->
        <geom type="mesh" class="visual" pos="5.55112e-17 0.175585 0.031625" quat="0.707107 -0 -0.707107 -1.10011e-16" mesh="zk_122" material="zk_122_material"/>
        <geom type="mesh" class="collision" pos="5.55112e-17 0.175585 0.031625" quat="0.707107 -0 -0.707107 -1.10011e-16" mesh="zk_122" material="zk_122_material"/>
        <!-- Part motor_1723_3_4 -->
        <geom type="mesh" class="visual" pos="0.00125 0.152735 0.031625" quat="1 -8.11122e-15 -1.31006e-14 1.43659e-14" mesh="motor_1723_3" material="motor_1723_3_material"/>
        <geom type="mesh" class="collision" pos="0.00125 0.152735 0.031625" quat="1 -8.11122e-15 -1.31006e-14 1.43659e-14" mesh="motor_1723_3" material="motor_1723_3_material"/>
        <!-- Link lamparm__wrist_head_2 -->
        <body name="lamparm__wrist_head_2" pos="2.55351e-15 0.185185 0.006125" quat="0.670659 0.670659 -0.224092 0.224092">
          <!-- Joint from lamparm__elbow_wrist to lamparm__wrist_head_2 -->
          <joint axis="0 0 1" name="4" type="hinge" range="-3.7865399953934267 2.4966453117861596" class="sts3215"/>
          <inertial pos="0.000541554 -0.000463734 -0.0217464" mass="0.0953804" fullinertia="2.19256e-05 1.7794e-05 1.16713e-05 6.98105e-08 -3.19269e-07 9.361e-07"/>
          <!-- Part lamparm__wrist_head_2 -->
          <geom type="mesh" class="visual" pos="0 -2.77556e-17 -1.38778e-17" quat="0 1 0 0" mesh="lamparm__wrist_head" material="lamparm__wrist_head_material"/>
          <geom type="mesh" class="collision" pos="0 -2.77556e-17 -1.38778e-17" quat="0 1 0 0" mesh="lamparm__wrist_head" material="lamparm__wrist_head_material"/>
          <!-- Part 金属舵盘_驱动__v2_5 -->
          <geom type="mesh" class="visual" pos="1.60982e-15 -0.0078 -0.05111" quat="0.707107 1.0961e-15 -0.707107 -8.93328e-16" mesh="金属舵盘_驱动__v2" material="金属舵盘_驱动__v2_material"/>
          <geom type="mesh" class="collision" pos="1.60982e-15 -0.0078 -0.05111" quat="0.707107 1.0961e-15 -0.707107 -8.93328e-16" mesh="金属舵盘_驱动__v2" material="金属舵盘_驱动__v2_material"/>
          <!-- Part 金属舵盘_从动__v2_5 -->
          <geom type="mesh" class="visual" pos="3.88578e-16 -0.03985 -0.03111" quat="2.56969e-15 0.707107 -7.77156e-16 -0.707107" mesh="金属舵盘_从动__v2" material="金属舵盘_从动__v2_material"/>
          <geom type="mesh" class="collision" pos="3.88578e-16 -0.03985 -0.03111" quat="2.56969e-15 0.707107 -7.77156e-16 -0.707107" mesh="金属舵盘_从动__v2" material="金属舵盘_从动__v2_material"/>
          <!-- Part pcb_chazuo_92_5 -->
          <geom type="mesh" class="visual" pos="1.94289e-16 0.0096 -0.01561" quat="0.707107 1.0961e-15 -0.707107 -8.93328e-16" mesh="pcb_chazuo_92" material="pcb_chazuo_92_material"/>
          <geom type="mesh" class="collision" pos="1.94289e-16 0.0096 -0.01561" quat="0.707107 1.0961e-15 -0.707107 -8.93328e-16" mesh="pcb_chazuo_92" material="pcb_chazuo_92_material"/>
          <!-- Part xg_ziji_16_5 -->
          <geom type="mesh" class="visual" pos="1.94289e-16 0.0096 -0.01561" quat="0.707107 1.0961e-15 -0.707107 -8.93328e-16" mesh="xg_ziji_16" material="xg_ziji_16_material"/>
          <geom type="mesh" class="collision" pos="1.94289e-16 0.0096 -0.01561" quat="0.707107 1.0961e-15 -0.707107 -8.93328e-16" mesh="xg_ziji_16" material="xg_ziji_16_material"/>
          <!-- Part ge_27_5 -->
          <geom type="mesh" class="visual" pos="8.32667e-17 0.0036 -0.04111" quat="0.5 0.5 -0.5 0.5" mesh="ge_27" material="ge_27_material"/>
          <geom type="mesh" class="collision" pos="8.32667e-17 0.0036 -0.04111" quat="0.5 0.5 -0.5 0.5" mesh="ge_27" material="ge_27_material"/>
          <!-- Part sg_ziji_15_5 -->
          <geom type="mesh" class="visual" pos="1.94289e-16 0.0096 -0.01561" quat="0.707107 1.0961e-15 -0.707107 -8.93328e-16" mesh="sg_ziji_15" material="sg_ziji_15_material"/>
          <geom type="mesh" class="collision" pos="1.94289e-16 0.0096 -0.01561" quat="0.707107 1.0961e-15 -0.707107 -8.93328e-16" mesh="sg_ziji_15" material="sg_ziji_15_material"/>
          <!-- Part zk_122_5 -->
          <geom type="mesh" class="visual" pos="1.94289e-16 0.0096 -0.01561" quat="0.707107 1.0961e-15 -0.707107 -8.93328e-16" mesh="zk_122" material="zk_122_material"/>
          <geom type="mesh" class="collision" pos="1.94289e-16 0.0096 -0.01561" quat="0.707107 1.0961e-15 -0.707107 -8.93328e-16" mesh="zk_122" material="zk_122_material"/>
          <!-- Part motor_1723_3_5 -->
          <geom type="mesh" class="visual" pos="0.00125 -0.01325 -0.01561" quat="1 1.45952e-14 2.05391e-14 2.58019e-14" mesh="motor_1723_3" material="motor_1723_3_material"/>
          <geom type="mesh" class="collision" pos="0.00125 -0.01325 -0.01561" quat="1 1.45952e-14 2.05391e-14 2.58019e-14" mesh="motor_1723_3" material="motor_1723_3_material"/>
          <!-- Link diffuser -->
          <body name="diffuser" pos="1.58207e-15 0.0192 -0.04111" quat="0.5 0.5 -0.5 0.5">
            <!-- Joint from lamparm__wrist_head_2 to diffuser -->
            <joint axis="0 0 1" name="5" type="hinge" range="-0.8533371981959901 2.288255455393803" class="sts3215"/>
            <inertial pos="-0.0641891 0.0560099 0.0186249" mass="0.0933113" fullinertia="0.000164418 0.000170062 0.000206169 2.06383e-05 7.21792e-11 4.01082e-10"/>
            <!-- Part diffuser -->
            <geom type="mesh" class="visual" pos="-0.0018837 0.00164368 0.03925" quat="0.643714 0.643714 0.292629 0.292629" mesh="diffuser" material="diffuser_material"/>
            <geom type="mesh" class="collision" pos="-0.0018837 0.00164368 0.03925" quat="0.643714 0.643714 0.292629 0.292629" mesh="diffuser" material="diffuser_material"/>
            <!-- Part lamphead -->
            <geom type="mesh" class="visual" pos="-0.0018837 0.00164368 0.03925" quat="0.643714 0.643714 0.292629 0.292629" mesh="lamphead" material="lamphead_material"/>
            <geom type="mesh" class="collision" pos="-0.0018837 0.00164368 0.03925" quat="0.643714 0.643714 0.292629 0.292629" mesh="lamphead" material="lamphead_material"/>
          </body>
        </body>
      </body>
    </body>
  </worldbody>
  <asset>
    <mesh file="xg_ziji_16.stl"/>
    <mesh file="ge_27.stl"/>
    <mesh file="金属舵盘_驱动__v2.stl"/>
    <mesh file="金属舵盘_从动__v2.stl"/>
    <mesh file="lamp_base_cover.stl"/>
    <mesh file="lamp_base.stl"/>
    <mesh file="lamparm__elbow_wrist.stl"/>
    <mesh file="lamparm__base_elbow.stl"/>
    <mesh file="diffuser.stl"/>
    <mesh file="sg_ziji_15.stl"/>
    <mesh file="lamparm__wrist_head.stl"/>
    <mesh file="lamphead.stl"/>
    <mesh file="motor_1723_3.stl"/>
    <mesh file="pcb_chazuo_92.stl"/>
    <mesh file="zk_122.stl"/>
    <material name="lamparm__base_elbow_material" rgba="0.301961 0.301961 0.301961 1"/>
    <material name="金属舵盘_驱动__v2_material" rgba="0.960784 0.960784 0.964706 1"/>
    <material name="金属舵盘_从动__v2_material" rgba="0.960784 0.960784 0.964706 1"/>
    <material name="pcb_chazuo_92_material" rgba="0.0980392 0.0980392 0.0980392 1"/>
    <material name="xg_ziji_16_material" rgba="0.0980392 0.0980392 0.0980392 1"/>
    <material name="ge_27_material" rgba="0.0980392 0.0980392 0.0980392 1"/>
    <material name="sg_ziji_15_material" rgba="0.0980392 0.0980392 0.0980392 1"/>
    <material name="zk_122_material" rgba="0.0980392 0.0980392 0.0980392 1"/>
    <material name="motor_1723_3_material" rgba="0.0980392 0.0980392 0.0980392 1"/>
    <material name="lamparm__wrist_head_material" rgba="0.301961 0.301961 0.301961 1"/>
    <material name="lamp_base_material" rgba="0.301961 0.301961 0.301961 1"/>
    <material name="lamp_base_cover_material" rgba="0.231373 0.380392 0.705882 1"/>
    <material name="lamparm__elbow_wrist_material" rgba="0.301961 0.301961 0.301961 1"/>
    <material name="diffuser_material" rgba="0.647059 0.647059 0.647059 1"/>
    <material name="lamphead_material" rgba="0.301961 0.301961 0.301961 1"/>
  </asset>
  <actuator>
    <position class="sts3215" name="2" joint="2" inheritrange="1"/>
    <position class="sts3215" name="1" joint="1" inheritrange="1"/>
    <position class="sts3215" name="3" joint="3" inheritrange="1"/>
    <position class="sts3215" name="4" joint="4" inheritrange="1"/>
    <position class="sts3215" name="5" joint="5" inheritrange="1"/>
  </actuator>
  <equality/>
</mujoco>
